<?xml version="1.0"?>
<!-- This URDF was automatically created by SolidWorks to URDF Exporter! Originally created by Stephen Brawner (brawner@gmail.com) 
     Commit Version: 1.6.0-4-g7f85cfe  Build Version: 1.6.7995.38578
     For more information, please see http://wiki.ros.org/sw_urdf_exporter -->
<robot
  name="4825ROBO_urdf">
  <link
    name="base_link">
    <inertial>
      <origin
        xyz="-1.4336E-17 2.3799E-17 0.028332"
        rpy="0 0 0" />
      <mass
        value="0.11473" />
      <inertia
        ixx="0.00017044"
        ixy="5.6954E-20"
        ixz="-3.326E-20"
        iyy="0.00017044"
        iyz="7.5202E-21"
        izz="0.00030848" />
    </inertial>
    <visual>
      <origin
        xyz="0 0 0"
        rpy="0 0 0" />
      <geometry>
        <mesh
          filename="package://marvin/meshes/base_link.STL" />
      </geometry>
      <material
        name="">
        <color
          rgba="0.79216 0.81961 0.93333 1" />
      </material>
    </visual>
    <collision>
      <origin
        xyz="0 0 0"
        rpy="0 0 0" />
      <geometry>
        <mesh
          filename="package://marvin/meshes/base_link.STL" />
      </geometry>
    </collision>
  </link>
  <link
    name="Link_1">
    <inertial>
      <origin
        xyz="0.014137 -0.013286 0.014927"
        rpy="0 0 0" />
      <mass
        value="0.29296" />
      <inertia
        ixx="0.00018813"
        ixy="-3.5366E-06"
        ixz="1.3871E-06"
        iyy="0.00019011"
        iyz="8.9891E-07"
        izz="0.00027081" />
    </inertial>
    <visual>
      <origin
        xyz="0 0 0"
        rpy="0 0 0" />
      <geometry>
        <mesh
          filename="package://marvin/meshes/Link_1.STL" />
      </geometry>
      <material
        name="">
        <color
          rgba="0.79216 0.81961 0.93333 1" />
      </material>
    </visual>
    <collision>
      <origin
        xyz="0 0 0"
        rpy="0 0 0" />
      <geometry>
        <mesh
          filename="package://marvin/meshes/Link_1.STL" />
      </geometry>
    </collision>
  </link>
  <joint
    name="Joint_1"
    type="revolute">
    <origin
      xyz="0 0 0.075"
      rpy="0 0 0" />
    <parent
      link="base_link" />
    <child
      link="Link_1" />
    <axis
      xyz="0 0 -1" />
    <limit
      lower="-1.57"
      upper="1.57"
      effort="4.5"
      velocity="6" />
  </joint>
  <link
    name="Link_2">
    <inertial>
      <origin
        xyz="-0.01529 9.2111E-06 0.074412"
        rpy="0 0 0" />
      <mass
        value="0.14158" />
      <inertia
        ixx="0.00038855"
        ixy="1.4982E-09"
        ixz="-2.863E-06"
        iyy="0.00036317"
        iyz="1.0303E-08"
        izz="4.5171E-05" />
    </inertial>
    <visual>
      <origin
        xyz="0 0 0"
        rpy="0 0 0" />
      <geometry>
        <mesh
          filename="package://marvin/meshes/Link_2.STL" />
      </geometry>
      <material
        name="">
        <color
          rgba="0.79216 0.81961 0.93333 1" />
      </material>
    </visual>
    <collision>
      <origin
        xyz="0 0 0"
        rpy="0 0 0" />
      <geometry>
        <mesh
          filename="package://marvin/meshes/Link_2.STL" />
      </geometry>
    </collision>
  </link>
  <joint
    name="Joint_2"
    type="revolute">
    <origin
      xyz="0.028 -0.032 0.035"
      rpy="0 0 0" />
    <parent
      link="Link_1" />
    <child
      link="Link_2" />
    <axis
      xyz="1 0 0" />
    <limit
      lower="-1.57"
      upper="1.57"
      effort="3.6"
      velocity="6" />
  </joint>
  <link
    name="Link_3">
    <inertial>
      <origin
        xyz="-0.032626 0.024536 0.005911"
        rpy="0 0 0" />
      <mass
        value="0.12591" />
      <inertia
        ixx="0.00012485"
        ixy="6.4467E-07"
        ixz="1.0192E-07"
        iyy="7.075E-05"
        iyz="-3.0888E-06"
        izz="6.9755E-05" />
    </inertial>
    <visual>
      <origin
        xyz="0 0 0"
        rpy="0 0 0" />
      <geometry>
        <mesh
          filename="package://marvin/meshes/Link_3.STL" />
      </geometry>
      <material
        name="">
        <color
          rgba="0.79216 0.81961 0.93333 1" />
      </material>
    </visual>
    <collision>
      <origin
        xyz="0 0 0"
        rpy="0 0 0" />
      <geometry>
        <mesh
          filename="package://marvin/meshes/Link_3.STL" />
      </geometry>
    </collision>
  </link>
  <joint
    name="Joint_3"
    type="revolute">
    <origin
      xyz="-0.032 0 0.15"
      rpy="0 0 0" />
    <parent
      link="Link_2" />
    <child
      link="Link_3" />
    <axis
      xyz="-1 0 0" />
    <limit
      lower="-1.57"
      upper="1.57"
      effort="3.6"
      velocity="6" />
  </joint>
  <link
    name="Link_4">
    <inertial>
      <origin
        xyz="0.0016172 -0.11918 -4.4632E-05"
        rpy="0 0 0" />
      <mass
        value="0.11509" />
      <inertia
        ixx="0.00027374"
        ixy="1.0274E-06"
        ixz="9.1368E-09"
        iyy="2.3485E-05"
        iyz="7.8574E-08"
        izz="0.00026579" />
    </inertial>
    <visual>
      <origin
        xyz="0 0 0"
        rpy="0 0 0" />
      <geometry>
        <mesh
          filename="package://marvin/meshes/Link_4.STL" />
      </geometry>
      <material
        name="">
        <color
          rgba="0.79216 0.81961 0.93333 1" />
      </material>
    </visual>
    <collision>
      <origin
        xyz="0 0 0"
        rpy="0 0 0" />
      <geometry>
        <mesh
          filename="package://marvin/meshes/Link_4.STL" />
      </geometry>
    </collision>
  </link>
  <joint
    name="Joint_4"
    type="revolute">
    <origin
      xyz="-0.0355 0.02 0.029"
      rpy="0 0 0" />
    <parent
      link="Link_3" />
    <child
      link="Link_4" />
    <axis
      xyz="0 -1 0" />
    <limit
      lower="-3.142"
      upper="3.142"
      effort="1.5"
      velocity="6" />
  </joint>
  <link
    name="Link_5">
    <inertial>
      <origin
        xyz="0.017814 -0.00093576 0.0016277"
        rpy="0 0 0" />
      <mass
        value="0.045999" />
      <inertia
        ixx="1.2178E-05"
        ixy="-1.4986E-09"
        ixz="-1.0441E-08"
        iyy="1.0214E-05"
        iyz="-1.91E-07"
        izz="6.787E-06" />
    </inertial>
    <visual>
      <origin
        xyz="0 0 0"
        rpy="0 0 0" />
      <geometry>
        <mesh
          filename="package://marvin/meshes/Link_5.STL" />
      </geometry>
      <material
        name="">
        <color
          rgba="0.79216 0.81961 0.93333 1" />
      </material>
    </visual>
    <collision>
      <origin
        xyz="0 0 0"
        rpy="0 0 0" />
      <geometry>
        <mesh
          filename="package://marvin/meshes/Link_5.STL" />
      </geometry>
    </collision>
  </link>
  <joint
    name="Joint_5"
    type="revolute">
    <origin
      xyz="0.0245 -0.18 0"
      rpy="0 0 0" />
    <parent
      link="Link_4" />
    <child
      link="Link_5" />
    <axis
      xyz="1 0 0" />
    <limit
      lower="-3.142"
      upper="3.142"
      effort="1.5"
      velocity="6" />
  </joint>
</robot>